<mujoco>
    <compiler meshdir="binary_meshes" angle="degree" />

    <option timestep="0.001" integrator="RK4" gravity="0 0 -9.81"/>

    <default>
        <joint limited="true" damping="30" armature="0.05" stiffness="0" actuatorfrcrange="-400 400"/>
        <!-- contype=0 conaffinity=0: structural geoms (torso, leg capsules) do not
         participate in any collision.  Feet override this to contype=1 so they
         collide with the floor (conaffinity=1) but not with each other. -->
        <geom condim="3" friction="1.5 0.005 0.0001" density="100" contype="0" conaffinity="0"/>
        <motor ctrllimited="true" ctrlrange="-1 1" gear="120"/>
    </default>

    <asset>
    <!--this scale makes it so that the robot is 1 meter in height, assuming mujoco base units are in meters-->
        <mesh name="base" file="TARS2_base_link_1.STL"  scale="2 2 2"/>
        <mesh name="middle_left" file="TARS2_middleslab_3.STL" scale="2 2 2"/>
        <mesh name="left" file="TARS2_leftslab_1.STL" scale="2 2 2"/>
        <mesh name="left_upper_arm" file="TARS2_leftarm1_1.STL"  scale="2 2 2"/>
        <mesh name="left_lower_arm" file="TARS2_leftarm2_1.STL" scale="2 2 2"/>
        <mesh name="middle_right" file="TARS2_middleslab_2.STL" scale="2 2 2"/>
        <mesh name="right" file="TARS2_rightslab_1.STL" scale="2 2 2"/>
        <mesh name="right_upper_arm" file="TARS2_rightarm1_1.STL" scale="2 2 2"/>
        <mesh name="right_lower_arm" file="TARS2_leftarm2_2.STL" scale="2 2 2"/>
    </asset>

    <worldbody>
        <light name="sun" pos="0 0 6" dir="0 0 -1" diffuse="1 1 1" specular="0.3 0.3 0.3"/>
        <geom name="floor" type="plane" size="50 50 0.1" rgba="0.75 0.85 0.75 1" friction="1.2 0.005 0.0001" contype="1" conaffinity="1" />
        <!--BASE-->
        <body name="base_link" euler="90 0 0">
            <joint type="free" />
            <geom type="mesh" mesh="base" rgba="0.35 0.45 0.75 1" contype="1" conaffinity="0" />
            <!--LEFT CHAIN-->
            <!--LEFT BASE LINK-->
            <body name="left_base_link">
                <joint name="r_lm" type="hinge" axis="1 0 0" pos="0 1 0.15" range="-355 355" damping="100" />
                <joint name="ud_lm" type="slide" axis="0 1 0" range="-0.2 0.2" damping="100" actuatorfrcrange="-400 400"/>
                <geom type="mesh" mesh="middle_left" rgba="0.55 0.65 0.45 1" contype="1" conaffinity="0" />
                <!--LEFT LINK-->
                <body name="left_link">
                    <joint name="r_l" type="hinge" axis="1 0 0" pos="0 1 0.15" range="-355 355" damping="100" />
                    <joint name="ud_l" type="slide" axis="0 1 0" range="-0.2 0.2" damping="100" actuatorfrcrange="-400 400"/>
                    <geom type="mesh" mesh="left" rgba="0.5 0.5 0.5 1" margin="0.0003" gap="0.0001" solref="0.01 1" solimp="0.9 0.95 0.001" contype="1" conaffinity="0" />
                    <!--LEFT UPPER ARM-->
                    <body name="left_upper_arm">
                        <joint name="r_lu" type="hinge" axis="1 0 0" pos="0 1 0.2" range="0 270" damping="100" />
                        <geom name="left_upper_arm_geom" type="mesh" mesh="left_upper_arm" rgba="0.5 0 0.5 1" margin="0.0003" gap="0.0001" solref="0.01 1" solimp="0.9 0.95 0.001" contype="1" conaffinity="0" />
                        <!--LEFT LOWER ARM-->
                        <body name="left_lower_arm">
                            <joint name="r_ll" type="hinge" axis="1 0 0" pos="0 2 0.15" range="0 355" damping="100" />
                            <geom name="left_lower_arm_geom" type="mesh" mesh="left_lower_arm" rgba="0 0.5 0.5 1" margin="0.0003" gap="0.0001" solref="0.01 1" solimp="0.9 0.95 0.001" contype="1" conaffinity="0" />
                        </body>
                    </body>
                </body>
            </body>
            <!--RIGHT CHAIN-->
            <!--RIGHT BASE LINK-->
            <body name="right_base_link">
                <joint name="r_rm" type="hinge" axis="1 0 0" pos="0 1 0.15" range="-355 355" damping="100" />
                <joint name="ud_rm" type="slide" axis="0 1 0" range="-0.2 0.2" damping="100" actuatorfrcrange="-400 400"/>
                <geom type="mesh" mesh="middle_right" rgba="0.55 0.65 0.45 1" contype="1" conaffinity="0" />
                <!--RIGHT LINK-->
                <body name="right_link">
                    <joint name="r_r" type="hinge" axis="1 0 0" pos="0 1 0.15" range="-355 355" damping="100" />
                    <joint name="ud_r" type="slide" axis="0 1 0" range="-0.2 0.2" damping="100" actuatorfrcrange="-400 400"/>
                    <geom type="mesh" mesh="right" rgba="0.5 0.5 0.5 1" margin="0.0003" gap="0.0001" solref="0.01 1" solimp="0.9 0.95 0.001" contype="1" conaffinity="0" />
                    <!--RIGHT UPPER ARM-->
                    <body name="right_upper_arm">
                        <joint name="r_ru" type="hinge" axis="1 0 0" pos="0 1 0.2" range="0 270" damping="100" />
                        <geom name="right_upper_arm_geom" type="mesh" mesh="right_upper_arm" rgba="0.5 0 0.5 1" margin="0.0003" gap="0.0001" solref="0.01 1" solimp="0.9 0.95 0.001" contype="1" conaffinity="0" />
                        <!--RIGHT LOWER ARM-->
                        <body name="right_lower_arm">
                            <joint name="r_rl" type="hinge" axis="1 0 0" pos="0 2 0.15" range="0 355" damping="100" />
                            <geom name="right_lower_arm_geom" type="mesh" mesh="right_lower_arm" rgba="0 0.5 0.5 1" margin="0.0003" gap="0.0001" solref="0.01 1" solimp="0.9 0.95 0.001" contype="1" conaffinity="0" />
                        </body>
                    </body>
                </body>
            </body>
        </body>
    </worldbody>

    <actuator>
        <position name="r_lm_pos" joint="r_lm" kp="2" ctrlrange="-355 355"/>
        <position name="ud_lm_pos" joint="ud_lm" kp="2" ctrlrange="-40 40"/>

        <position name="r_l_pos" joint="r_l" kp="2" ctrlrange="-355 355"/>
        <position name="ud_l_pos" joint="ud_l" kp="2" ctrlrange="-40 40"/>

        <position name="r_lu_pos" joint="r_lu" kp="2" ctrlrange="0 355"/>
        <position name="r_ll_pos" joint="r_ll" kp="2" ctrlrange="0 355"/>

        <position name="r_rm_pos" joint="r_rm" kp="2" ctrlrange="-355 355"/>
        <position name="ud_rm_pos" joint="ud_rm" kp="2" ctrlrange="-40 40"/>

        <position name="r_r_pos" joint="r_r" kp="2" ctrlrange="-355 355"/>
        <position name="ud_r_pos" joint="ud_r" kp="2" ctrlrange="-40 40"/>

        <position name="r_ru_pos" joint="r_ru" kp="2" ctrlrange="0 355"/>
        <position name="r_rl_pos" joint="r_rl" kp="2" ctrlrange="0 355"/>

    </actuator>

    <keyframe>
        <!--         base link  x y z   w   x     y z     r_lm  ud_lm  r_l  ud_l     r_lu    r_ll  r_rm  ud_rm   r_r  ud_r  r_ru   r_rl-->
        <key name="init0" qpos="0 0 0.2 0.5 0.866 0 0     0     0     -1    0        2.2     2     0     0      -1    0     2.2     2"
            ctrl="0 0 -114 0 250.8 228 0 0 -114 0 250.8 228" /> <!--x with middle links tilted forward and side links tilted back-->
        <key name="init1" qpos="0 0 0.2 0.5 0.866 0 0     0     0      0    0        2.2     2     0     0       0    0     2.2     2"
            ctrl="0 0 0 0 250.8 228 0 0 0 0 250.8 228" /> <!--standing straight up-->
        <key name="init2" qpos="0 0 0.2 0.5 0.866 0 0    -1     0      1    0        1.2     2    -1     0       1    0     1.2     2"
            ctrl="-114 0 114 0 136.8 228 -114 0 114 0 136.8 228"/> <!--x with middle links tilted back and side links tilted forward-->
        <key name="init3" qpos="0 0 0.2 0.5 0.866 0 0    -1     0      0    0        2.6     2     0    0       -1    0     2.6     2"
            ctrl="-114 0 0 0 296.4 228 0 0 -114 0 296.4 228"/> <!--x with middle right link tilted forward and all other links tilted back-->
        <key name="init4" qpos="0 0 0.2 0.5 0.866 0 0     0     0     -1    0        2.6     2    -1    0        0    0     2.6     2"
            ctrl="0 0 -114 0 296.4 228 -114 0 0 0 296.4 228"/> <!--x with middle left link tilted forward and all other links tilted back-->
    </keyframe>

</mujoco>
