<?xml version="1.0" encoding="utf-8"?>
<!-- This URDF was automatically created by SolidWorks to URDF Exporter! Originally created by Stephen Brawner (brawner@gmail.com) 
     Commit Version: 1.6.0-4-g7f85cfe  Build Version: 1.6.7995.38578
     For more information, please see http://wiki.ros.org/sw_urdf_exporter -->
<robot
  name="TARS">
  <link
    name="base_link">
    <inertial>
      <origin
        xyz="0.000650945499891475 5.68186261335763E-16 6.76327045890586E-18"
        rpy="0 0 0" />
      <mass
        value="15.6061275835347" />
      <inertia
        ixx="1.342656303608"
        ixy="1.48562697261322E-16"
        ixz="-2.8294147550437E-18"
        iyy="0.0406509464655723"
        iyz="1.0021287407368E-16"
        izz="1.34253193836181" />
    </inertial>
    <visual>
      <origin
        xyz="0 0 0"
        rpy="0 0 0" />
      <geometry>
        <mesh
          filename="package://TARS/meshes/base_link.obj" />
      </geometry>
      <material
        name="">
        <color
          rgba="0.792156862745098 0.819607843137255 0.933333333333333 1" />
      </material>
    </visual>
    <collision>
      <origin
        xyz="0 0 0"
        rpy="0 0 0" />
      <geometry>
        <mesh
          filename="package://TARS/meshes/base_link.obj" />
      </geometry>
    </collision>
  </link>
  <link
    name="right_link">
    <inertial>
      <origin
        xyz="0.00494432219717394 -0.0359666729743279 -0.00475356305172504"
        rpy="0 0 0" />
      <mass
        value="13.6731594878913" />
      <inertia
        ixx="1.15686403106967"
        ixy="-0.0177995734020957"
        ixz="-0.00235249433610559"
        iyy="0.0350226658912917"
        iyz="0.0176585752299687"
        izz="1.15709321194351" />
    </inertial>
    <visual>
      <origin
        xyz="0 0 0"
        rpy="0 0 0" />
      <geometry>
        <mesh
          filename="package://TARS/meshes/right_link.obj" />
      </geometry>
      <material
        name="">
        <color
          rgba="0.792156862745098 0.819607843137255 0.933333333333333 1" />
      </material>
    </visual>
    <collision>
      <origin
        xyz="0 0 0"
        rpy="0 0 0" />
      <geometry>
        <mesh
          filename="package://TARS/meshes/right_link.obj" />
      </geometry>
    </collision>
  </link>
  <joint
    name="right_joint"
    type="continuous">
    <origin
      xyz="-0.125 0 0"
      rpy="1.5708 0 0" />
    <parent
      link="base_link" />
    <child
      link="right_link" />
    <axis
      xyz="1 0 0" />
  </joint>
  <link
    name="right_arm_upper_link">
    <inertial>
      <origin
        xyz="-0.0333672500409003 0.220176680127642 0.00207498884988712"
        rpy="0 0 0" />
      <mass
        value="1.81341478536214" />
      <inertia
        ixx="0.041637358084647"
        ixy="0.000605021778306699"
        ixz="-6.79968020586111E-05"
        iyy="0.00115646678181214"
        iyz="-0.000583400807235026"
        izz="0.0416452417250091" />
    </inertial>
    <visual>
      <origin
        xyz="0 0 0"
        rpy="0 0 0" />
      <geometry>
        <mesh
          filename="package://TARS/meshes/right_arm_upper_link.obj" />
      </geometry>
      <material
        name="">
        <color
          rgba="0.792156862745098 0.819607843137255 0.933333333333333 1" />
      </material>
    </visual>
    <collision>
      <origin
        xyz="0 0 0"
        rpy="0 0 0" />
      <geometry>
        <mesh
          filename="package://TARS/meshes/right_arm_upper_link.obj" />
      </geometry>
    </collision>
  </link>
  <joint
    name="right_arm_upper_joint"
    type="revolute">
    <origin
      xyz="0 0 0.03125"
      rpy="0 0 0" />
    <parent
      link="right_link" />
    <child
      link="right_arm_upper_link" />
    <axis
      xyz="1 0 0" />
    <limit
      lower="0"
      upper="1.5708"
      effort="0"
      velocity="0" />
  </joint>
  <link
    name="right_arm_lower_link">
    <inertial>
      <origin
        xyz="-0.015625 -0.1128477991555 -1.56125112837913E-16"
        rpy="0 0 0" />
      <mass
        value="0.24442176150459" />
      <inertia
        ixx="0.00129708116063147"
        ixy="-3.6189151799195E-21"
        ixz="-1.51250336383087E-24"
        iyy="3.95383680650096E-05"
        iyz="-8.58901581028341E-20"
        izz="0.00129732498031134" />
    </inertial>
    <visual>
      <origin
        xyz="0 0 0"
        rpy="0 0 0" />
      <geometry>
        <mesh
          filename="package://TARS/meshes/right_arm_lower_link.obj" />
      </geometry>
      <material
        name="">
        <color
          rgba="0.792156862745098 0.819607843137255 0.933333333333333 1" />
      </material>
    </visual>
    <collision>
      <origin
        xyz="0 0 0"
        rpy="0 0 0" />
      <geometry>
        <mesh
          filename="package://TARS/meshes/right_arm_lower_link.obj" />
      </geometry>
    </collision>
  </link>
  <joint
    name="right_arm_lower_joint"
    type="revolute">
    <origin
      xyz="0 0.48802 -0.015625"
      rpy="0 0 0" />
    <parent
      link="right_arm_upper_link" />
    <child
      link="right_arm_lower_link" />
    <axis
      xyz="1 0 0" />
    <limit
      lower="0"
      upper="3.1416"
      effort="0"
      velocity="0" />
  </joint>
  <link
    name="left_middle_link">
    <inertial>
      <origin
        xyz="0.0631509454998915 5.96003406485335E-16 4.97617020908452E-17"
        rpy="0 0 0" />
      <mass
        value="15.6061275835347" />
      <inertia
        ixx="1.342656303608"
        ixy="1.6130269726115E-16"
        ixz="-2.86989322218019E-18"
        iyy="0.0406509464655723"
        iyz="1.05454596295606E-16"
        izz="1.34253193836181" />
    </inertial>
    <visual>
      <origin
        xyz="0 0 0"
        rpy="0 0 0" />
      <geometry>
        <mesh
          filename="package://TARS/meshes/left_middle_link.obj" />
      </geometry>
      <material
        name="">
        <color
          rgba="0.792156862745098 0.819607843137255 0.933333333333333 1" />
      </material>
    </visual>
    <collision>
      <origin
        xyz="0 0 0"
        rpy="0 0 0" />
      <geometry>
        <mesh
          filename="package://TARS/meshes/left_middle_link.obj" />
      </geometry>
    </collision>
  </link>
  <joint
    name="left_middle_joint"
    type="continuous">
    <origin
      xyz="0.0625 0 0"
      rpy="1.5708 0 0" />
    <parent
      link="base_link" />
    <child
      link="left_middle_link" />
    <axis
      xyz="1 0 0" />
  </joint>
  <link
    name="left_link">
    <inertial>
      <origin
        xyz="0.0582430613949537 -0.0364425280442357 -0.00481645480376195"
        rpy="0 0 0" />
      <mass
        value="13.4946196715515" />
      <inertia
        ixx="1.15635737646566"
        ixy="0.0174615332355522"
        ixz="0.00230781699698032"
        iyy="0.0344789618730616"
        iyz="0.0176895040135128"
        izz="1.15611723913357" />
    </inertial>
    <visual>
      <origin
        xyz="0 0 0"
        rpy="0 0 0" />
      <geometry>
        <mesh
          filename="package://TARS/meshes/left_link.obj" />
      </geometry>
      <material
        name="">
        <color
          rgba="0.792156862745098 0.819607843137255 0.933333333333333 1" />
      </material>
    </visual>
    <collision>
      <origin
        xyz="0 0 0"
        rpy="0 0 0" />
      <geometry>
        <mesh
          filename="package://TARS/meshes/left_link.obj" />
      </geometry>
    </collision>
  </link>
  <joint
    name="left_joint"
    type="continuous">
    <origin
      xyz="0.125 0 0"
      rpy="0 0 0" />
    <parent
      link="left_middle_link" />
    <child
      link="left_link" />
    <axis
      xyz="1 0 0" />
  </joint>
  <link
    name="left_arm_upper_link">
    <inertial>
      <origin
        xyz="0.0333672500409004 0.220176680127642 0.00207498884988713"
        rpy="0 0 0" />
      <mass
        value="1.81341478536214" />
      <inertia
        ixx="0.0416373580846469"
        ixy="-0.000605021778306698"
        ixz="6.79968020586111E-05"
        iyy="0.00115646678181214"
        iyz="-0.000583400807235025"
        izz="0.041645241725009" />
    </inertial>
    <visual>
      <origin
        xyz="0 0 0"
        rpy="0 0 0" />
      <geometry>
        <mesh
          filename="package://TARS/meshes/left_arm_upper_link.obj" />
      </geometry>
      <material
        name="">
        <color
          rgba="0.792156862745098 0.819607843137255 0.933333333333333 1" />
      </material>
    </visual>
    <collision>
      <origin
        xyz="0 0 0"
        rpy="0 0 0" />
      <geometry>
        <mesh
          filename="package://TARS/meshes/left_arm_upper_link.obj" />
      </geometry>
    </collision>
  </link>
  <joint
    name="left_arm_upper_joint"
    type="revolute">
    <origin
      xyz="0.0625 0 0.03125"
      rpy="0 0 0" />
    <parent
      link="left_link" />
    <child
      link="left_arm_upper_link" />
    <axis
      xyz="1 0 0" />
    <limit
      lower="0"
      upper="1.5708"
      effort="0"
      velocity="0" />
  </joint>
  <link
    name="left_arm_lower_link">
    <inertial>
      <origin
        xyz="0.015625 -0.1128477991555 -3.29597460435593E-17"
        rpy="0 0 0" />
      <mass
        value="0.24442176150459" />
      <inertia
        ixx="0.00129708116063147"
        ixy="-3.6189151799195E-21"
        ixz="-1.51250336383087E-24"
        iyy="3.95383680650096E-05"
        iyz="-8.63037484091106E-20"
        izz="0.00129732498031134" />
    </inertial>
    <visual>
      <origin
        xyz="0 0 0"
        rpy="0 0 0" />
      <geometry>
        <mesh
          filename="package://TARS/meshes/left_arm_lower_link.obj" />
      </geometry>
      <material
        name="">
        <color
          rgba="0.792156862745098 0.819607843137255 0.933333333333333 1" />
      </material>
    </visual>
    <collision>
      <origin
        xyz="0 0 0"
        rpy="0 0 0" />
      <geometry>
        <mesh
          filename="package://TARS/meshes/left_arm_lower_link.obj" />
      </geometry>
    </collision>
  </link>
  <joint
    name="left_arm_lower_joint"
    type="revolute">
    <origin
      xyz="0 0.48802 -0.015625"
      rpy="0 0 0" />
    <parent
      link="left_arm_upper_link" />
    <child
      link="left_arm_lower_link" />
    <axis
      xyz="1 0 0" />
    <limit
      lower="0"
      upper="3.1416"
      effort="0"
      velocity="0" />
  </joint>
</robot>